Workbook

Sheet قياس الأداء للربع الأول
A1: قياس الأداء الإستراتيجي و التشغيلي للربع الأول لعام 2026م
A2: رمزالهدف | B2: رمزالمؤشر | C2: المؤشر | D2: نوع المؤشر | E2: وحدة القياس | F2: الإتجاه | G2: دورية القياس | H2: البيانات المطلوبة للقياس | I2: الإدارة المالكة | J2: خط الأساس | K2: مستهدف عام 2026 | L2: المستهدف للربع الأول | M2: المتحقق الفعلي للربع الأول | N2: نسبة الإنجاز | O2: قيمة الانحراف | P2: نسبة الانحراف | Q2: ماذا حصل؟ | R2: كيف حصل؟ | S2: إرفاق شواهد الربع الأول | T2: حالة الإعتماد | U2: توصيات قسم الاستراتيجية | V2: الأداء السنوي | W2: نسبة التقدم نحو المستهدف السنوي | X2: شامل
A3: ع1 | B3: ع1-1 | C3: متوسط ما تتحصل عليه الأسرة من الجمعية | D3: استراتيجي | E3: ريال | F3: كلما زاد كان أفضل | G3: ربع سنوي | H3: تقرير مالي بالمعونات المقدمة للأسر المستفيدة وعدد الأسر المستفيدة | I3: إدارة الرعاية و التمكين | J3: 0 | K3: 20000 | L3: 4000 | N3: =IF(AND($T3="معتمد",$L3>0),$M3/$L3,"") | O3: =IF($T3="معتمد",$M3-$L3,"") | P3: =IF(AND($T3="معتمد",$L3>0),($M3-$L3)/$L3,"") | V3: =IF($T3<>"معتمد","",IFERROR((IF(AND($T3="معتمد",$L3>0),$M3,0))/(IF(AND($T3="معتمد",$L3>0),$L3,0)),"")) | W3: =IF(AND($T3="معتمد",$K3>0),(IF($T3="معتمد",$M3,0))/$K3,"") | X3: =A3&B3&C3&D3&E3&F3&G3&H3&I3&J3&K3&L3&M3&N3&O3&P3&Q3&R3&S3&T3&U3&V3&W3 -> ع1ع1-1متوسط ما تتحصل عليه الأسرة من الجمعية استراتيجيريالكلما زاد كان أفضلربع سنويتقرير مالي بالمعونات المقدمة للأسر المستفيدة وعدد الأسر المستفيدةإدارة الرعاية و التمكين0200004000 | AA3: البحث عن:
A4: ع1 | B4: ع2-1 | C4: نسبة الأسر التي تم توفير الاحتياجات الضرورية لها | D4: استراتيجي | E4: نسبة | F4: كلما زاد كان أفضل | G4: ربع سنوي | H4: تقرير يصف الإحتياجات الضرورية المعرّفة في الجمعية والأسر المستفيدة منها | I4: إدارة الرعاية و التمكين | J4: 0 | K4: 0.94 | L4: 0.94 | M4: 0.94 | N4: =IF(AND($T4="معتمد",$L4>0),$M4/$L4,"") | O4: =IF($T4="معتمد",$M4-$L4,"") | P4: =IF(AND($T4="معتمد",$L4>0),($M4-$L4)/$L4,"") | Q4: أولًا:تم تغذية بطاقات منافذ لجميع الأسر النشطة وذلك في التاريخ المعتمد 15 من كل شهر ميلادي بمبالغ مخصصة وفق اللوائح المعمول بها لكل أسرة حسب عدد أفرادها،وبلغ عدد الأسر المكفولة في شهر يناير / 151 أسرة واجمالي مبلغ الكفالة لشهر يناير / 66400 ريال ثانيًا:تم تغذية بطاقات منافذ لجميع الأسر النشطة وذلك في التاريخ المعتمد 15 من كل شهر ميلادي بمبالغ مخصصة وفق اللوائح المعمول بها لكل أسرة حسب عدد أفرادها وبلغ عدد الأسر المكفولة في شهر فبراير/ 172 أسرة واجمالي مبلغ الكفالة لشهر يناير / 72900 ريال ثالثًا:تم تغذية بطاقات منافذ لجميع الأسر النشطة وذلك في التاريخ المعتمد 15 من كل شهر ميلادي بمبالغ مخصصة وفق اللوائح المعمول بها لكل أسرة حسب عدد أفرادها وبلغ عدد الأسر المكفولة في شهر فبراير/ 171 أسرة واجمالي مبلغ الكفالة لشهر يناير / 73450 ريال رابعًا:تم تغذية بطاقات منافذ للأسر التي لديها طلاب بالمرحلة الابتدائية والمتوسطة والثانوية بمبلع الحقيبة المدرسية المخصص لكل طالب وهو 150ريال وبلغ اجمالي عدد الطلاب: 235 واجمالي تغذية البطاقات: 35250 ريال خامسًا:تم السداد للحالات الطارئة من مشروع امان وذلك لبعض المديونيات المتعثرة لدى المستفيدين كما بلغ عدد المستفيدين للبرنامج 17 مستفيدعلى ثلاثة مراحل متفاوتة ، باجمالي مبلغ السداد 12446684ريال سادسًا: تم اكمال منزل مستفيد وتعتبر الحالة الثالثة والأخيرة الالحاقية لبرنامج اكمال المنازل في 2025 وبلغ تكلفة المشروع لهذه الحالة 168212 ريال ، كما بلغ عدد المستفيدي لكامل المشروع ثلاثة مستفيين باجمالي تكلفة المشروع 240000 ريال سابعًا: المطابخ : تم تركيب 5 مطابخ لخمسة مستفيدين الأجهزة الكهربائية:تم صرف وتوصيل 7 أجهزة كهربائية للمستفيدين بعدد: 4 أفران+ 1 غسالة + 2 ثلاجة . الأثاث: تم صرف كنب لثلاثة أسر مستفيدة مستحقة وايصاله لمنازلهم. ثامنًا: صرف سلال غذائية على جميع الأسر المستفيدة لجميع فئات الجمعية وتسليمها لهم من خلال مستودع الجمعية تاسعًا: تم تنظيم رحلة لآداء مناسك العمرة وانضمام 33 مستفيد في يوم الاثنين الموافق 15 رمضان لمدة ثلاثة أيام كما شملت رحلة العمرة أهم الخدمات (النقل والسكن والوجبات الرئيسية) عاشرًا: تم تغذية بطاقات منافذ لجميع الأسر النشطة وذلك في التاريخ المعتمد 9 مارس يوم الاثنين بمبالغ مخصصة وفق اللوائح المعمول بها لكل أسرة حسب عدد أفرادها وذلك ملاءمة لتغذية الكفالة الشهرية والمبالغ المقدرة للأسر وبلغ عدد الأسر التي تم دعمهم بكسوة العيد / 173 أسرة واجمالي مبلغ كسوة عيد الفطر / 73750 ريال، تم توزيع هدايا العيد على جميع الأسر المستفيدة وتم تحديد الهدية وهي من محل قوتي للحلويات بلغ عدد المستفيدين من هدية العيد 450 أسرة ، وذلك بكبلغ وقدره 10440 ريال+ هدايا ابناء الاسر 300 هدية، تم تصنيف المستفيدين المستحقين لزكاة الفطر ، وتوزيع وتوزيع الفطرة عليهم ، وذلك وفق سياسة تنظيم للزمان والمكان باشعار المستفيدين ومتابعتهم | R4: أولاً:اثر التحديث السنوي للأسر المستفيدة وفرز النشطين والمستحقين ومن تم تسجيله وقبوله خلال هذه الفترة ، وخلال تنشيط ملفاتهم يتم تحديد العدد والعمر مقابل المبلغ المحدد لكل فرد وفق اللوائح المعمول بها، ثم تصنيف القائمة ورفع طلب التغذية في نظام منافذ واشعار المستفيدين بذلك. ثانياً:التحقق من استمرارية استحقاق النشطين وقبول المتقدمين الجدد ، يتم تحديد العدد والعمر مقابل المبلغ المحدد لكل فرد وفق اللوائح المعمول بها، ثم تصنيف القائمة ورفع طلب التغذية في نظام منافذ واشعار المستفيدين بذلك. ثالثاً:التحقق من استمرارية استحقاق النشطين وقبول المتقدمين الجدد ، يتم تحديد العدد والعمر مقابل المبلغ المحدد لكل فرد وفق اللوائح المعمول بها، ثم تصنيف القائمة ورفع طلب التغذية في نظام منافذ واشعار المستفيدين بذلك. رابعاً:فرز وحصر المستفيدين الرعويين ، من خلال النشطين على نظام خير وتم تقدير مبلغ موحد وهو 400 ريال لكل الأسر تحليلاً لمشتريات سابقة، ومن ثم رفع طلب تغذية على نظام منافذ ، وتحديد منافذ العنايى واشعار المستفيدين بذلك . خامساً:من خلال فرز التابعين حسب العمر والمرحلة الدراسية في نظام خير والتواصل مع الأسر والتحقق منها ، وتم تحديد مبلغ لكل الطلاب واعتماده وايداعه في حسابهم في منافذ واشعارهم بذلك. سادساً:تم حصر المستفيدين المديونين وذلك من خلال التواصل والاستبيانات وفرز المستحقين للسداد حسب سياسة المشروع ، ومن ثم رفع القوائم للمالية واعتماد السداد واشعار المستفيدين. سابعاً:من خلال الزيارات الميدانية للباحثين للأسر المستفيدة تم حصر وفرز من كان وضع منزل غير صالح ويحتاج لتدخل واكمال بناء وترميم ، ورفع تقارير بالصور والمرئيات للإدارة واعتماد الحالات المرشحة ، ومن ثم تم التعاقد مع الشركات المقاولة واعتمادة وبدء التنفيذ والانتهاء منه. ثامنا:"تم فرز وحصر طلبات المستفيدين المرفوعة في نظام خير حسب كل برنامج وتوفر الطلبات والتأكد من استحقاقيتهم للطلبات المرفوعة من خلال الزيارات الميدانية واعتماد الاستحقاق ومن بعد ذلك يتم صرف لكل مستفيد * الأجهزة الكهربائية وتوزيعها في زيارة مؤسسة الراجحي الخيرية عبر زيارات ميدانية للأسر المستحقة. * الأثاث (الكنبات) تم استقبالها من الداعم في مستودع الجمعية وتم تسليمها للمستفيدين المستحقين. * المطابخ تم الاتفاق مع شركة مطابخ وفق اتفاقية الداعم للبرنامج بزيارة مسبقة لأخذ المقاسات الدقيقة ومن ثم تركيبها بشكل كامل. " تاسعاً:تم استقبال سلال غذائية من المتبرعين، ثم تم صرف سلال غذائية على جميع الأسر المستفيدة لجميع فئات الجمعية واشعارهم بذلك وتسليمها لهم من خلال مستودع الجمعية. عاشراً:"تم حصر المستفيدين من خلال ارسال نموذج بالرغبة في الانضمام ومتابعة التواصل مع المستفيد بالتحقق والاستحقاق وتسجيل مرافق معه ان وجد وتنظيم العمرة باتفاق مع شركة (المنفذ المثالث) وتم تعيين مشرف للعمرة ومتطوع متعاون لترتيب وتنظيم العمرة بشكل متكامل ومنظم" الحادي عشر:فرز وحصر المستفيدين الرعويين ، من خلال النشطين على نظام خير وتم تقدير مبلغ كسوة العيد مماثلاُ لمبلغ الكفالة الشهرية، ومن ثم رفع طلب تغذية على نظام منافذ ، وتحديد منافذ الكسوة واشعار المستفيدين بذلك. الثاني عشر:تم فرز المستفيدين المستحقين لهدية العيد من فئتي الرعوي والتنموي وتحديد اجمالي العدد، ومن ثم البحث عن صنف مناسب لتقديمه هدية عيد للمستفيدين، والعمل على المعاملات والمطالبات المالية، واستلامها وترتيبها وتجهيزها وتقديمها للأسر مع زكاة الفطر. الثالث عشر:تم فرز المستفيدين المستحقين زكاة الفطر من جميع الفئات الرعوي والتنموي وفئة هـ وتحديد الكمية المقدرة لكل أسرة حسب عدد أفرادها، ويتم تسليمها للأسر المستفيدة وفق سياسة تنظيم معتمدة وتعمم على الأسر المستفيدة. | S4: مؤشر نسبة الأسر التي تم توفير الاحتياجات الضرورية لها | V4: =IF($T4<>"معتمد","",IFERROR((IF(AND($T4="معتمد",$L4>0),$M4,0))/(IF(AND($T4="معتمد",$L4>0),$L4,0)),"")) | W4: =IF(AND($T4="معتمد",$K4>0),(IF($T4="معتمد",$M4,0))/$K4,"") | X4: =A4&B4&C4&D4&E4&F4&G4&H4&I4&J4&K4&L4&M4&N4&O4&P4&Q4&R4&S4&T4&U4&V4&W4 -> ع1ع2-1نسبة الأسر التي تم توفير الاحتياجات الضرورية لها استراتيجينسبةكلما زاد كان أفضلربع سنويتقرير يصف الإحتياجات الضرورية المعرّفة في الجمعية والأسر المستفيدة منهاإدارة الرعاية و التمكين00.940.940.94أولًا:تم تغذية بطاقات منافذ لجميع الأسر النشطة وذلك في التاريخ المعتمد 15 من كل شهر ميلادي بمبالغ مخصصة وفق اللوائح المعمول بها لكل أسرة حسب عدد أفرادها،وبلغ عدد الأسر المكفولة في شهر يناير / 151 أسرة واجمالي مبلغ الكفالة لشهر يناير / 66400 ريال ثانيًا:تم تغذية بطاقات منافذ لجميع الأسر النشطة وذلك في التاريخ المعتمد 15 من كل شهر ميلادي بمبالغ مخصصة وفق اللوائح المعمول بها لكل أسرة حسب عدد أفرادها وبلغ عدد الأسر المكفولة في شهر فبراير/ 172 أسرة واجمالي مبلغ الكفالة لشهر يناير / 72900 ريال ثالثًا:تم تغذية بطاقات منافذ لجميع الأسر النشطة وذلك في التاريخ المعتمد 15 من كل شهر ميلادي بمبالغ مخصصة وفق اللوائح المعمول بها لكل أسرة حسب عدد أفرادها وبلغ عدد الأسر المكفولة في شهر فبراير/ 171 أسرة واجمالي مبلغ الكفالة لشهر يناير / 73450 ريال رابعًا:تم تغذية بطاقات منافذ للأسر التي لديها طلاب بالمرحلة الابتدائية والمتوسطة والثانوية بمبلع الحقيبة المدرسية المخصص لكل طالب وهو 150ريال وبلغ اجمالي عدد الطلاب: 235 واجمالي تغذية البطاقات: 35250 ريال خامسًا:تم السداد للحالات الطارئة من مشروع امان وذلك لبعض المديونيات المتعثرة لدى المستفيدين كما بلغ عدد المستفيدين للبرنامج 17 مستفيدعلى ثلاثة مراحل متفاوتة ، باجمالي مبلغ السداد 12446684ريال سادسًا: تم اكمال منزل مستفيد وتعتبر الحالة الثالثة والأخيرة الالحاقية لبرنامج اكمال المنازل في 2025 وبلغ تكلفة المشروع لهذه الحالة 168212 ريال ، كما بلغ عدد المستفيدي لكامل المشروع ثلاثة مستفيين باجمالي تكلفة المشروع 240000 ريال سابعًا: المطابخ : تم تركيب 5 مطابخ لخمسة مستفيدين الأجهزة الكهربائية:تم صرف وتوصيل 7 أجهزة كهربائية للمستفيدين بعدد: 4 أفران+ 1 غسالة + 2 ثلاجة . الأثاث: تم صرف كنب لثلاثة أسر مستفيدة مستحقة وايصاله لمنازلهم. ثامنًا: صرف سلال غذائية على جميع الأسر المستفيدة لجميع فئات الجمعية وتسليمها لهم من خلال مستودع الجمعية تاسعًا: تم تنظيم رحلة لآداء مناسك العمرة وانضمام 33 مستفيد في يوم الاثنين الموافق 15 رمضان لمدة ثلاثة أيام كما شملت رحلة العمرة أهم الخدمات (النقل والسكن والوجبات الرئيسية) عاشرًا: تم تغذية بطاقات منافذ لجميع الأسر النشطة وذلك في التاريخ المعتمد 9 مارس يوم الاثنين بمبالغ مخصصة وفق اللوائح المعمول بها لكل أسرة حسب عدد أفرادها وذلك ملاءمة لتغذية الكفالة الشهرية والمبالغ المقدرة للأسر وبلغ عدد الأسر التي تم دعمهم بكسوة العيد / 173 أسرة واجمالي مبلغ كسوة عيد الفطر / 73750 ريال، تم توزيع هدايا العيد على جميع الأسر المستفيدة وتم تحديد الهدية وهي من محل قوتي للحلويات بلغ عدد المستفيدين من هدية العيد 450 أسرة ، وذلك بكبلغ وقدره 10440 ريال+ هدايا ابناء الاسر 300 هدية، تم تصنيف المستفيدين المستحقين لزكاة الفطر ، وتوزيع وتوزيع الفطرة عليهم ، وذلك وفق سياسة تنظيم للزمان والمكان باشعار المستفيدين ومتابعتهم أولاً:اثر التحديث السنوي للأسر المستفيدة وفرز النشطين والمستحقين ومن تم تسجيله وقبوله خلال هذه الفترة ، وخلال تنشيط ملفاتهم يتم تحديد العدد والعمر مقابل المبلغ المحدد لكل فرد وفق اللوائح المعمول بها، ثم تصنيف القائمة ورفع طلب التغذية في نظام منافذ واشعار المستفيدين بذلك. ثانياً:التحقق من استمرارية استحقاق النشطين وقبول المتقدمين الجدد ، يتم تحديد العدد والعمر مقابل المبلغ المحدد لكل فرد وفق اللوائح المعمول بها، ثم تصنيف القائمة ورفع طلب التغذية في نظام منافذ واشعار المستفيدين بذلك. ثالثاً:التحقق من استمرارية استحقاق النشطين وقبول المتقدمين الجدد ، يتم تحديد العدد والعمر مقابل المبلغ المحدد لكل فرد وفق اللوائح المعمول بها، ثم تصنيف القائمة ورفع طلب التغذية في نظام منافذ واشعار المستفيدين بذلك. رابعاً:فرز وحصر المستفيدين الرعويين ، من خلال النشطين على نظام خير وتم تقدير مبلغ موحد وهو 400 ريال لكل الأسر تحليلاً لمشتريات سابقة، ومن ثم رفع طلب تغذية على نظام منافذ ، وتحديد منافذ العنايى واشعار المستفيدين بذلك . خامساً:من خلال فرز التابعين حسب العمر والمرحلة الدراسية في نظام خير والتواصل مع الأسر والتحقق منها ، وتم تحديد مبلغ لكل الطلاب واعتماده وايداعه في حسابهم في منافذ واشعارهم بذلك. سادساً:تم حصر المستفيدين المديونين وذلك من خلال التواصل والاستبيانات وفرز المستحقين للسداد حسب سياسة المشروع ، ومن ثم رفع القوائم للمالية واعتماد السداد واشعار المستفيدين. سابعاً:من خلال الزيارات الميدانية للباحثين للأسر المستفيدة تم حصر وفرز من كان وضع منزل غير صالح ويحتاج لتدخل واكمال بناء وترميم ، ورفع تقارير بالصور والمرئيات للإدارة واعتماد الحالات المرشحة ، ومن ثم تم التعاقد مع الشركات المقاولة واعتمادة وبدء التنفيذ والانتهاء منه. ثامنا:"تم فرز وحصر طلبات المستفيدين المرفوعة في نظام خير حسب كل برنامج وتوفر الطلبات والتأكد من استحقاقيتهم للطلبات المرفوعة من خلال الزيارات الميدانية واعتماد الاستحقاق ومن بعد ذلك يتم صرف لكل مستفيد * الأجهزة الكهربائية وتوزيعها في زيارة مؤسسة الراجحي الخيرية عبر زيارات ميدانية للأسر المستحقة. * الأثاث (الكنبات) تم استقبالها من الداعم في مستودع الجمعية وتم تسليمها للمستفيدين المستحقين. * المطابخ تم الاتفاق مع شركة مطابخ وفق اتفاقية الداعم للبرنامج بزيارة مسبقة لأخذ المقاسات الدقيقة ومن ثم تركيبها بشكل كامل. " تاسعاً:تم استقبال سلال غذائية من المتبرعين، ثم تم صرف سلال غذائية على جميع الأسر المستفيدة لجميع فئات الجمعية واشعارهم بذلك وتسليمها لهم من خلال مستودع الجمعية. عاشراً:"تم حصر المستفيدين من خلال ارسال نموذج بالرغبة في الانضمام ومتابعة التواصل مع المستفيد بالتحقق والاستحقاق وتسجيل مرافق معه ان وجد وتنظيم العمرة باتفاق مع شركة (المنفذ المثالث) وتم تعيين مشرف للعمرة ومتطوع متعاون لترتيب وتنظيم العمرة بشكل متكامل ومنظم" الحادي عشر:فرز وحصر المستفيدين الرعويين ، من خلال النشطين على نظام خير وتم تقدير مبلغ كسوة العيد مماثلاُ لمبلغ الكفالة الشهرية، ومن ثم رفع طلب تغذية على نظام منافذ ، وتحديد منافذ الكسوة واشعار المستفيدين بذلك. الثاني عشر:تم فرز المستفيدين المستحقين لهدية العيد من فئتي الرعوي والتنموي وتحديد اجمالي العدد، ومن ثم البحث عن صنف مناسب لتقديمه هدية عيد للمستفيدين، والعمل على المعاملات والمطالبات المالية، واستلامها وترتيبها وتجهيزها وتقديمها للأسر مع زكاة الفطر. الثالث عشر:تم فرز المستفيدين المستحقين زكاة الفطر من جميع الفئات الرعوي والتنموي وفئة هـ وتحديد الكمية المقدرة لكل أسرة حسب عدد أفرادها، ويتم تسليمها للأسر المستفيدة وفق سياسة تنظيم معتمدة وتعمم على الأسر المستفيدة.مؤشر نسبة الأسر التي تم توفير الاحتياجات الضرورية لها
A5: ع2 | B5: ع1-2 | C5: عدد المستفيدين الذين تم تأهيلهم | D5: استراتيجي | E5: مستفيد | F5: كلما زاد كان أفضل | G5: ربع سنوي | H5: قائمة ببرامج التأهيل وعدد المستفيدين من كل برنامج | I5: إدارة الرعاية و التمكين | J5: 0 | K5: 450 | L5: 100 | M5: 102 | N5: =IF(AND($T5="معتمد",$L5>0),$M5/$L5,"") | O5: =IF($T5="معتمد",$M5-$L5,"") | P5: =IF(AND($T5="معتمد",$L5>0),($M5-$L5)/$L5,"") | Q5: أولاً:تم ربط عدد (34) مشترك/ة من أبناء وبنات الأسر المستفيدة في برنامج غراس الرمضاني، بالتعاون مع عدد من الأكاديميات الشريكة. ثانياً:تم تكريم عدد ( 27) متفوقًا ومتفوقة في جائزة التفوق للفصل الأول، وتوزيع الشهادات والجوائز في حفل منظم، بالإضافة إلى إطلاق التسجيل في الجائزة للفصل الدراسي الثاني. ثالثاً:تم تأهيل عدد (20) من الخريجات في دورة المقابلات الوظيفية "كيف تعرف بذاتك " المقامة بالتعاون مع صندوق تنمية الموارد البشرية – هدف، كما تم تأهيل عدد (2) من الخريجات في دورة المكياج الاحترافي مع المدربة سمية الغفيلي، بالاضافة الى تأهيل عدد ( 7) من الخريجين من خلال دورة المهارات الناعمة وفن الاتصال المقامة بالتعاون مع مركز التنمية الاجتماعية – جادة 30، وأيضًا تم ربط مستفيد واحد في برنامج "أساسيات ريادة الأعمال في استثمار المواهب والقدرات" المقام في مركز العثيم فاب لاب، كما تم حصول عدد ( 10 ) من الخريجين في دورة السكرتارية و المهارات الادارية و المنفذة من وحدة التمكين لتابعة للضمان الإجتماعي . رابعاً:تم خلال الربع دراسة حالة تعليمية واحدة لأحد طلاب الأسر المستفيدة المتعثرين في سداد الرسوم. | R5: اولاً:تم ذلك من خلال تفعيل الشراكة مع أكاديمية رموز المستقبل ومركز سواعد وأفكار للتدريب، وإعداد خطة تنفيذية متكاملة تضمنت تحديد الأدوار والضوابط المنظمة للعمل مع الشركاء، إضافة إلى تطبيق أدوات قياس أثر قبلية وبعدية لقياس مستوى التحسن لدى المشاركين وضمان جودة المخرجات. ثانياً:تم ذلك عبر إطلاق التسجيل، ترشيح المستفيدين، ثم فرزهم وفق مسارات الجائزة المعتمدة مسار التميز ومسار التقدم ، مع تنظيم الحفل الرسمي لتكريم الفائزين وتوزيع الشهادات. ثالثاً:تم ذلك من خلال بناء قاعدة بيانات للخريجين وتحديد احتياجاتهم التدريبية والمهنية، ثم ربطهم بالدورات المناسبة بالتعاون مع الجهات الشريكة. كما نُفذت دورة المقابلات الوظيفية استجابةً لاحتياج الخريجين وتهيئتهم قبل المقابلات الوظيفية مع شركة مخازن العناية. رابعاً:تم ذلك من خلال التحقق من استحقاق الحالة وفق شروط لائحة التعليم، وطلب المرفقات اللازمة ، ثم رفعها للإدارة لاعتمادها واستكمال إجراءات السداد. | S5: مؤشر عدد المستفيدين الذين تم تأهيلهم | V5: =IF($T5<>"معتمد","",IFERROR((IF(AND($T5="معتمد",$L5>0),$M5,0))/(IF(AND($T5="معتمد",$L5>0),$L5,0)),"")) | W5: =IF(AND($T5="معتمد",$K5>0),(IF($T5="معتمد",$M5,0))/$K5,"") | X5: =A5&B5&C5&D5&E5&F5&G5&H5&I5&J5&K5&L5&M5&N5&O5&P5&Q5&R5&S5&T5&U5&V5&W5 -> ع2ع1-2عدد المستفيدين الذين تم تأهيلهماستراتيجيمستفيدكلما زاد كان أفضلربع سنويقائمة ببرامج التأهيل وعدد المستفيدين من كل برنامجإدارة الرعاية و التمكين0450100102أولاً:تم ربط عدد (34) مشترك/ة من أبناء وبنات الأسر المستفيدة في برنامج غراس الرمضاني، بالتعاون مع عدد من الأكاديميات الشريكة. ثانياً:تم تكريم عدد ( 27) متفوقًا ومتفوقة في جائزة التفوق للفصل الأول، وتوزيع الشهادات والجوائز في حفل منظم، بالإضافة إلى إطلاق التسجيل في الجائزة للفصل الدراسي الثاني. ثالثاً:تم تأهيل عدد (20) من الخريجات في دورة المقابلات الوظيفية "كيف تعرف بذاتك " المقامة بالتعاون مع صندوق تنمية الموارد البشرية – هدف، كما تم تأهيل عدد (2) من الخريجات في دورة المكياج الاحترافي مع المدربة سمية الغفيلي، بالاضافة الى تأهيل عدد ( 7) من الخريجين من خلال دورة المهارات الناعمة وفن الاتصال المقامة بالتعاون مع مركز التنمية الاجتماعية – جادة 30، وأيضًا تم ربط مستفيد واحد في برنامج "أساسيات ريادة الأعمال في استثمار المواهب والقدرات" المقام في مركز العثيم فاب لاب، كما تم حصول عدد ( 10 ) من الخريجين في دورة السكرتارية و المهارات الادارية و المنفذة من وحدة التمكين لتابعة للضمان الإجتماعي . رابعاً:تم خلال الربع دراسة حالة تعليمية واحدة لأحد طلاب الأسر المستفيدة المتعثرين في سداد الرسوم.اولاً:تم ذلك من خلال تفعيل الشراكة مع أكاديمية رموز المستقبل ومركز سواعد وأفكار للتدريب، وإعداد خطة تنفيذية متكاملة تضمنت تحديد الأدوار والضوابط المنظمة للعمل مع الشركاء، إضافة إلى تطبيق أدوات قياس أثر قبلية وبعدية لقياس مستوى التحسن لدى المشاركين وضمان جودة المخرجات. ثانياً:تم ذلك عبر إطلاق التسجيل، ترشيح المستفيدين، ثم فرزهم وفق مسارات الجائزة المعتمدة مسار التميز ومسار التقدم ، مع تنظيم الحفل الرسمي لتكريم الفائزين وتوزيع الشهادات. ثالثاً:تم ذلك من خلال بناء قاعدة بيانات للخريجين وتحديد احتياجاتهم التدريبية والمهنية، ثم ربطهم بالدورات المناسبة بالتعاون مع الجهات الشريكة. كما نُفذت دورة المقابلات الوظيفية استجابةً لاحتياج الخريجين وتهيئتهم قبل المقابلات الوظيفية مع شركة مخازن العناية. رابعاً:تم ذلك من خلال التحقق من استحقاق الحالة وفق شروط لائحة التعليم، وطلب المرفقات اللازمة ، ثم رفعها للإدارة لاعتمادها واستكمال إجراءات السداد.مؤشر عدد المستفيدين الذين تم تأهيلهم
A6: ع2 | B6: ع2-2 | C6: عدد الأفراد الذين استغنوا عن خدمات الجمعية | D6: استراتيجي | E6: أسرة | F6: كلما زاد كان أفضل | G6: ربع سنوي | H6: قائمة بمستفيدي الجمعية و الأفراد الذين استغنوا عن خدمات الجمعية | I6: إدارة الرعاية و التمكين | J6: 0 | K6: 50 | L6: 5 | M6: 5 | N6: =IF(AND($T6="معتمد",$L6>0),$M6/$L6,"") | O6: =IF($T6="معتمد",$M6-$L6,"") | P6: =IF(AND($T6="معتمد",$L6>0),($M6-$L6)/$L6,"") | Q6: تم توظيف خمسة من الخريجين في عدد من الجهات في القطاع الخاص، حيث التحقت خريجتان بالعمل في شركة حلول أتمال ، وخريجة واحدة في مجمع الفيحاء الطبي، خريج واحد في مدارس الخير الأهلية، وخريج في شركة أمني المتحدة للحراسات الأمنية . | R6: تم العمل مع الخريجين على تحسين جاهزيتهم لسوق العمل من خلال إعداد السير الذاتية وإلحاقهم بعدد من الدورات التطويرية، إضافة إلى متابعتهم في البحث عن فرص العمل وترشيح المناسب منها، حتى تم قبولهم والتحاقهم بالعمل. | S6: مؤشر عدد الأفراد الذين استغنوا عن خدمات الجمعية | V6: =IF($T6<>"معتمد","",IFERROR((IF(AND($T6="معتمد",$L6>0),$M6,0))/(IF(AND($T6="معتمد",$L6>0),$L6,0)),"")) | W6: =IF(AND($T6="معتمد",$K6>0),(IF($T6="معتمد",$M6,0))/$K6,"") | X6: =A6&B6&C6&D6&E6&F6&G6&H6&I6&J6&K6&L6&M6&N6&O6&P6&Q6&R6&S6&T6&U6&V6&W6 -> ع2ع2-2عدد الأفراد الذين استغنوا عن خدمات الجمعيةاستراتيجيأسرةكلما زاد كان أفضلربع سنويقائمة بمستفيدي الجمعية و الأفراد الذين استغنوا عن خدمات الجمعيةإدارة الرعاية و التمكين05055تم توظيف خمسة من الخريجين في عدد من الجهات في القطاع الخاص، حيث التحقت خريجتان بالعمل في شركة حلول أتمال ، وخريجة واحدة في مجمع الفيحاء الطبي، خريج واحد في مدارس الخير الأهلية، وخريج في شركة أمني المتحدة للحراسات الأمنية .تم العمل مع الخريجين على تحسين جاهزيتهم لسوق العمل من خلال إعداد السير الذاتية وإلحاقهم بعدد من الدورات التطويرية، إضافة إلى متابعتهم في البحث عن فرص العمل وترشيح المناسب منها، حتى تم قبولهم والتحاقهم بالعمل.مؤشر عدد الأفراد الذين استغنوا عن خدمات الجمعية
A7: ع3 | B7: ع1-3 | C7: عدد المبادرات المنفذة لحماية الأسر من مسببات الفقر | D7: استراتيجي | E7: مبادرة | F7: كلما زاد كان أفضل | G7: ربع سنوي | H7: تقرير بالمبادرات المنفذة لحماية الأسر من مسببات الفقر | I7: إدارة التكافل المجتمعي | J7: 0 | K7: 7 | L7: 0 | N7: =IF(AND($T7="معتمد",$L7>0),$M7/$L7,"") | O7: =IF($T7="معتمد",$M7-$L7,"") | P7: =IF(AND($T7="معتمد",$L7>0),($M7-$L7)/$L7,"") | V7: =IF($T7<>"معتمد","",IFERROR((IF(AND($T7="معتمد",$L7>0),$M7,0))/(IF(AND($T7="معتمد",$L7>0),$L7,0)),"")) | W7: =IF(AND($T7="معتمد",$K7>0),(IF($T7="معتمد",$M7,0))/$K7,"") | X7: =A7&B7&C7&D7&E7&F7&G7&H7&I7&J7&K7&L7&M7&N7&O7&P7&Q7&R7&S7&T7&U7&V7&W7 -> ع3ع1-3عدد المبادرات المنفذة لحماية الأسر من مسببات الفقراستراتيجيمبادرةكلما زاد كان أفضلربع سنويتقرير بالمبادرات المنفذة لحماية الأسر من مسببات الفقرإدارة التكافل المجتمعي070
A8: ع3 | B8: ع2-3 | C8: عدد المستفيدين من المبادرات | D8: استراتيجي | E8: مستفيد | F8: كلما زاد كان أفضل | G8: ربع سنوي | H8: تقرير بالمبادرات المنفذة لحماية الأسر من مسببات الفقر، ونوعها وعدد المستفيدين في كل مبادرة | I8: إدارة التكافل المجتمعي | J8: 0 | K8: 40000 | L8: 11000 | N8: =IF(AND($T8="معتمد",$L8>0),$M8/$L8,"") | O8: =IF($T8="معتمد",$M8-$L8,"") | P8: =IF(AND($T8="معتمد",$L8>0),($M8-$L8)/$L8,"") | V8: =IF($T8<>"معتمد","",IFERROR((IF(AND($T8="معتمد",$L8>0),$M8,0))/(IF(AND($T8="معتمد",$L8>0),$L8,0)),"")) | W8: =IF(AND($T8="معتمد",$K8>0),(IF($T8="معتمد",$M8,0))/$K8,"") | X8: =A8&B8&C8&D8&E8&F8&G8&H8&I8&J8&K8&L8&M8&N8&O8&P8&Q8&R8&S8&T8&U8&V8&W8 -> ع3ع2-3عدد المستفيدين من المبادرات استراتيجيمستفيدكلما زاد كان أفضلربع سنويتقرير بالمبادرات المنفذة لحماية الأسر من مسببات الفقر، ونوعها وعدد المستفيدين في كل مبادرةإدارة التكافل المجتمعي04000011000 | AC8: رمزالهدف | AD8: رمزالمؤشر | AE8: اسم المؤشر | AF8: نوع المؤشر | AG8: وحدة القياس | AH8: الإتجاه | AI8: دورية القياس | AJ8: البيانات المطلوبة للقياس | AK8: الإدارة المالكة | AL8: خط الأساس | AM8: مستهدف عام 2026 | AN8: المستهدف للربع الأول | AO8: المتحقق الفعلي للربع الأول | AP8: نسبة الإنجاز Q1 | AQ8: قيمة الانحراف Q1 | AR8: نسبة الانحراف Q1 | AS8: ماذا حصل Q1؟ | AT8: كيف حصل Q1؟ | AU8: إرفاق شواهد Q1 | AV8: حالة الإعتماد | AW8: توصيات قسم الاستراتيجية | AX8: الأداء السنوي
A9: ع4 | B9: ع1-4 | C9: عدد مشاريع المشاركة المجتمعية التي نفذتها الجمعية | D9: استراتيجي | E9: مشروع | F9: كلما زاد كان أفضل | G9: ربع سنوي | H9: قائمة ببرامج المشاركة المجتمعية المنفذة | I9: إدارة التكافل المجتمعي | J9: 0 | K9: 7 | L9: 0 | M9: 5 | N9: =IF(AND($T9="معتمد",$L9>0),$M9/$L9,"") | O9: =IF($T9="معتمد",$M9-$L9,"") | P9: =IF(AND($T9="معتمد",$L9>0),($M9-$L9)/$L9,"") | Q9: تم خلال الربع الأول تنفيذ خمسة مشاريع نوعية (الإفطار السيار، زكاة الفطر، ابتلت العروق، إفطار أهالي القصيم، مبادرة الحي المتكافل)، حيث تم توزيع وجبات إفطار صائم عبر منافذ متعددة في الطرق والإشارات والمواقع الحيوية، إضافة إلى تقديم الإفطار في مخيم أهالي القصيم كجزء من نطاق المشروع، مما ساهم في خدمة شريحة واسعة من المستفيدين. كما تم جمع وتوزيع زكاة الفطر على المستحقين في الوقت الشرعي، مع تحقيق وصولها للفئات المستحقة بكفاءة. وفي جانب التكافل المجتمعي، تم ربط الأسر المتكافلة بالأسر المستفيدة لتوفير وجبات الإفطار، إضافة إلى إشراك المطاعم في دعم الأسر المحتاجة، مما عزز الأثر الاجتماعي ووسّع دائرة المستفيدين. | R9: تم تحقيق ذلك من خلال التخطيط المسبق وإعداد خطط تشغيلية واضحة لكل مشروع، مع تنظيم فرق العمل وتوزيع الأدوار بشكل دقيق، وتشغيل منافذ ونقاط توزيع ميدانية متعددة وفق آلية منظمة. كما تم تنفيذ العمل عبر عدة مسارات تكاملية، شملت: إدارة مواقع التوزيع، تجهيز مخيمات الإفطار، تنظيم عمليات استلام وتخزين وتوزيع زكاة الفطر، والتنسيق بين الأسر المتبرعة والأسر المستفيدة مع نقل الوجبات عبر المتطوعين، إضافة إلى بناء شراكات مع المطاعم لدعم الأسر المحتاجة. وقد دعمت هذه الجهود بمتابعة ميدانية مستمرة، وتنسيق فعّال مع الجهات المشاركة، مما أسهم في رفع جودة التنفيذ وتحقيق المستهدفات بكفاءة عالية | S9: https://alzaadsa-my.sharepoint.com/:f:/g/personal/pmo_alzaad_org_sa/IgDvFW9U-8gJTKea7hCXZCtxASzaXIeOtAqarTli4uSIAjc?e=kL9T17 | V9: =IF($T9<>"معتمد","",IFERROR((IF(AND($T9="معتمد",$L9>0),$M9,0))/(IF(AND($T9="معتمد",$L9>0),$L9,0)),"")) | W9: =IF(AND($T9="معتمد",$K9>0),(IF($T9="معتمد",$M9,0))/$K9,"") | X9: =A9&B9&C9&D9&E9&F9&G9&H9&I9&J9&K9&L9&M9&N9&O9&P9&Q9&R9&S9&T9&U9&V9&W9 -> ع4ع1-4عدد مشاريع المشاركة المجتمعية التي نفذتها الجمعيةاستراتيجيمشروعكلما زاد كان أفضلربع سنويقائمة ببرامج المشاركة المجتمعية المنفذةإدارة التكافل المجتمعي0705تم خلال الربع الأول تنفيذ خمسة مشاريع نوعية (الإفطار السيار، زكاة الفطر، ابتلت العروق، إفطار أهالي القصيم، مبادرة الحي المتكافل)، حيث تم توزيع وجبات إفطار صائم عبر منافذ متعددة في الطرق والإشارات والمواقع الحيوية، إضافة إلى تقديم الإفطار في مخيم أهالي القصيم كجزء من نطاق المشروع، مما ساهم في خدمة شريحة واسعة من المستفيدين. كما تم جمع وتوزيع زكاة الفطر على المستحقين في الوقت الشرعي، مع تحقيق وصولها للفئات المستحقة بكفاءة. وفي جانب التكافل المجتمعي، تم ربط الأسر المتكافلة بالأسر المستفيدة لتوفير وجبات الإفطار، إضافة إلى إشراك المطاعم في دعم الأسر المحتاجة، مما عزز الأثر الاجتماعي ووسّع دائرة المستفيدين.تم تحقيق ذلك من خلال التخطيط المسبق وإعداد خطط تشغيلية واضحة لكل مشروع، مع تنظيم فرق العمل وتوزيع الأدوار بشكل دقيق، وتشغيل منافذ ونقاط توزيع ميدانية متعددة وفق آلية منظمة. كما تم تنفيذ العمل عبر عدة مسارات تكاملية، شملت: إدارة مواقع التوزيع، تجهيز مخيمات الإفطار، تنظيم عمليات استلام وتخزين وتوزيع زكاة الفطر، والتنسيق بين الأسر المتبرعة والأسر المستفيدة مع نقل الوجبات عبر المتطوعين، إضافة إلى بناء شراكات مع المطاعم لدعم الأسر المحتاجة. وقد دعمت هذه الجهود بمتابعة ميدانية مستمرة، وتنسيق فعّال مع الجهات المشاركة، مما أسهم في رفع جودة التنفيذ وتحقيق المستهدفات بكفاءة عاليةhttps://alzaadsa-my.sharepoint.com/:f:/g/personal/pmo_alzaad_org_sa/IgDvFW9U-8gJTKea7hCXZCtxASzaXIeOtAqarTli4uSIAjc?e=kL9T17 | AB9: {=_xlfn._xlws.FILTER(الجدول4[],ISNUMBER(SEARCH(AA3,#REF!)),"غير موجود")} -> #VALUE! | AC9: #VALUE! | AD9: #VALUE! | AE9: #VALUE! | AF9: #VALUE! | AG9: #VALUE! | AH9: #VALUE! | AI9: #VALUE! | AJ9: #VALUE! | AK9: #VALUE! | AL9: #VALUE! | AM9: #VALUE! | AN9: #VALUE! | AO9: #VALUE! | AP9: #VALUE! | AQ9: #VALUE! | AR9: #VALUE! | AS9: #VALUE! | AT9: #VALUE! | AU9: #VALUE! | AV9: #VALUE! | AW9: #VALUE! | AX9: #VALUE! | AY9: د4د1-4عدد الشراكات الفاعلةشراكةكلما زاد كان أفضلربع سنويقائمة ببيانات الشراكات الفاعلة التي أقامتها الجمعيةإدارة الإتصال المؤسسي080250.125
B10: ع2-4 | C10: عدد المشاركين من المجتمع في برامج المشاركة المجتمعية | D10: استراتيجي | E10: مشارك | F10: كلما زاد كان أفضل | G10: ربع سنوي | H10: قائمة ببرامج المشاركة المجتمعية المنفذة وعدد المشاركين | I10: إدارة التكافل المجتمعي | J10: 0 | K10: 70000 | L10: 20000 | M10: 33205 | N10: =IF(AND($T10="معتمد",$L10>0),$M10/$L10,"") | O10: =IF($T10="معتمد",$M10-$L10,"") | P10: =IF(AND($T10="معتمد",$L10>0),($M10-$L10)/$L10,"") | Q10: شهدت مشاريع الربع الأول (زكاة الفطر، الإفطار السيار، ابتلت العروق، إفطار أهالي القصيم، مبادرة الحي المتكافل) مشاركة مجتمعية واسعة ومتنوعة، حيث أسهم في تنفيذها عدد كبير من المشاركين من فئات مختلفة. شملت هذه المشاركة: • المتطوعين: الذين شاركوا في جميع المشاريع، خصوصًا في التشغيل الميداني والتنظيم والتوزيع. • المزكّين: الذين أسهموا في مشروع زكاة الفطر من خلال إخراج زكواتهم عبر المنظومة. • الأسر المتكافلة: التي شاركت في مشروع ابتلت العروق عبر تقديم وجبات الإفطار للأسر المستفيدة. • أفراد المجتمع: الذين أسهموا بجهود مباشرة أو غير مباشرة في دعم وتنفيذ المبادرات. وقد انعكس هذا التنوع في المشاركين على تعزيز روح التكافل المجتمعي، ورفع مستوى التفاعل مع المشاريع، وزيادة أثرها وانتشارها | R10: تحقق هذا المستوى من المشاركة من خلال: • نشر الفرص وإتاحتها بوضوح: الإعلان عن المشاريع والفرص عبر القنوات الإعلامية، من خلال نشر المنشورات التعريفية والتوعوية التي عرّفت بالمبادرات وآليات المشاركة فيها. • تفعيل الحملات الإعلامية: الاستمرار في نشر المحتوى المرتبط بالمشاريع، مما ساهم في رفع الوعي وتحفيز المجتمع على الانخراط. • تيسير الوصول للفرص: إتاحة فرص التطوع والعمل المجتمعي والتكافل بشكل واضح ومنظم، بحيث يستطيع الفرد اختيار المسار المناسب له (متطوع، مزكّي، أسرة متكافلة). • تنوع مجالات المشاركة: تصميم المشاريع بحيث تشمل مجالات متعددة (ميدانية، مالية، تكافلية)، مما جذب شرائح مختلفة من المجتمع. • تعزيز مفهوم التكافل: إبراز نماذج المشاركة المجتمعية (مثل الأسر المتكافلة)، مما شجّع الآخرين على التفاعل والمساهمة. • التنظيم والمتابعة: إدارة المشاركين بآلية واضحة، مع متابعة مستمرة لضمان استمرارية المشاركة وجودتها | S10: https://alzaadsa-my.sharepoint.com/:f:/g/personal/pmo_alzaad_org_sa/IgCDUBH8AxwnR5n1t-a_pKQnAaAUFpeqYxzm1efcwfylJlc?e=zq4J83 | V10: =IF($T10<>"معتمد","",IFERROR((IF(AND($T10="معتمد",$L10>0),$M10,0))/(IF(AND($T10="معتمد",$L10>0),$L10,0)),"")) | W10: =IF(AND($T10="معتمد",$K10>0),(IF($T10="معتمد",$M10,0))/$K10,"") | X10: =A10&B10&C10&D10&E10&F10&G10&H10&I10&J10&K10&L10&M10&N10&O10&P10&Q10&R10&S10&T10&U10&V10&W10 -> ع2-4عدد المشاركين من المجتمع في برامج المشاركة المجتمعيةاستراتيجيمشارككلما زاد كان أفضلربع سنويقائمة ببرامج المشاركة المجتمعية المنفذة وعدد المشاركينإدارة التكافل المجتمعي0700002000033205شهدت مشاريع الربع الأول (زكاة الفطر، الإفطار السيار، ابتلت العروق، إفطار أهالي القصيم، مبادرة الحي المتكافل) مشاركة مجتمعية واسعة ومتنوعة، حيث أسهم في تنفيذها عدد كبير من المشاركين من فئات مختلفة. شملت هذه المشاركة: • المتطوعين: الذين شاركوا في جميع المشاريع، خصوصًا في التشغيل الميداني والتنظيم والتوزيع. • المزكّين: الذين أسهموا في مشروع زكاة الفطر من خلال إخراج زكواتهم عبر المنظومة. • الأسر المتكافلة: التي شاركت في مشروع ابتلت العروق عبر تقديم وجبات الإفطار للأسر المستفيدة. • أفراد المجتمع: الذين أسهموا بجهود مباشرة أو غير مباشرة في دعم وتنفيذ المبادرات. وقد انعكس هذا التنوع في المشاركين على تعزيز روح التكافل المجتمعي، ورفع مستوى التفاعل مع المشاريع، وزيادة أثرها وانتشارهاتحقق هذا المستوى من المشاركة من خلال: • نشر الفرص وإتاحتها بوضوح: الإعلان عن المشاريع والفرص عبر القنوات الإعلامية، من خلال نشر المنشورات التعريفية والتوعوية التي عرّفت بالمبادرات وآليات المشاركة فيها. • تفعيل الحملات الإعلامية: الاستمرار في نشر المحتوى المرتبط بالمشاريع، مما ساهم في رفع الوعي وتحفيز المجتمع على الانخراط. • تيسير الوصول للفرص: إتاحة فرص التطوع والعمل المجتمعي والتكافل بشكل واضح ومنظم، بحيث يستطيع الفرد اختيار المسار المناسب له (متطوع، مزكّي، أسرة متكافلة). • تنوع مجالات المشاركة: تصميم المشاريع بحيث تشمل مجالات متعددة (ميدانية، مالية، تكافلية)، مما جذب شرائح مختلفة من المجتمع. • تعزيز مفهوم التكافل: إبراز نماذج المشاركة المجتمعية (مثل الأسر المتكافلة)، مما شجّع الآخرين على التفاعل والمساهمة. • التنظيم والمتابعة: إدارة المشاركين بآلية واضحة، مع متابعة مستمرة لضمان استمرارية المشاركة وجودتهاhttps://alzaadsa-my.sharepoint.com/:f:/g/personal/pmo_alzaad_org_sa/IgCDUBH8AxwnR5n1t-a_pKQnAaAUFpeqYxzm1efcwfylJlc?e=zq4J83
A11: م1 | B11: م1-1 | C11: صافي أرباح المصادر الثابتة | D11: استراتيجي | E11: ريال | F11: كلما زاد كان أفضل | G11: ربع سنوي | H11: تقرير مالي بالإيرادات والمصروفات المالية للجمعية | I11: إدارة الشؤون المالية و الإدارية | J11: 0 | K11: 1500000 | L11: 300000 | M11: 175718.91 | N11: =IF(AND($T11="معتمد",$L11>0),$M11/$L11,"") | O11: =IF($T11="معتمد",$M11-$L11,"") | P11: =IF(AND($T11="معتمد",$L11>0),($M11-$L11)/$L11,"") | Q11: تحصيل إدارة االأملاك من قبل المستأجرين مقابل استئجارهم | R11: أعمال ترميم طارئة لعقار وقف المنتزه بقيمة (86,250 ريال) متأخرات (68,500) | S11: https://alzaadsa-my.sharepoint.com/:f:/g/personal/pmo_alzaad_org_sa/IgB58WHETVQ_Q4DgceOIZzkCAQUMWuQqZPxBrs7NtLkrCWk?e=dMWBUU | V11: =IF($T11<>"معتمد","",IFERROR((IF(AND($T11="معتمد",$L11>0),$M11,0))/(IF(AND($T11="معتمد",$L11>0),$L11,0)),"")) | W11: =IF(AND($T11="معتمد",$K11>0),(IF($T11="معتمد",$M11,0))/$K11,"") | X11: =A11&B11&C11&D11&E11&F11&G11&H11&I11&J11&K11&L11&M11&N11&O11&P11&Q11&R11&S11&T11&U11&V11&W11 -> م1م1-1صافي أرباح المصادر الثابتةاستراتيجيريالكلما زاد كان أفضلربع سنويتقرير مالي بالإيرادات والمصروفات المالية للجمعيةإدارة الشؤون المالية و الإدارية01500000300000175718.91تحصيل إدارة االأملاك من قبل المستأجرين مقابل استئجارهم أعمال ترميم طارئة لعقار وقف المنتزه بقيمة (86,250 ريال) متأخرات (68,500) https://alzaadsa-my.sharepoint.com/:f:/g/personal/pmo_alzaad_org_sa/IgB58WHETVQ_Q4DgceOIZzkCAQUMWuQqZPxBrs7NtLkrCWk?e=dMWBUU
A12: م1 | B12: م2-1 | C12: صافي أرباح الاستثمارات | D12: استراتيجي | E12: ريال | F12: كلما زاد كان أفضل | G12: ربع سنوي | H12: تقرير بإيرادات ومصروفات الإستثمارات المالية | I12: إدارة الإستدامة | J12: 0 | K12: 10350000 | L12: 0 | N12: =IF(AND($T12="معتمد",$L12>0),$M12/$L12,"") | O12: =IF($T12="معتمد",$M12-$L12,"") | P12: =IF(AND($T12="معتمد",$L12>0),($M12-$L12)/$L12,"") | V12: =IF($T12<>"معتمد","",IFERROR((IF(AND($T12="معتمد",$L12>0),$M12,0))/(IF(AND($T12="معتمد",$L12>0),$L12,0)),"")) | W12: =IF(AND($T12="معتمد",$K12>0),(IF($T12="معتمد",$M12,0))/$K12,"") | X12: =A12&B12&C12&D12&E12&F12&G12&H12&I12&J12&K12&L12&M12&N12&O12&P12&Q12&R12&S12&T12&U12&V12&W12 -> م1م2-1صافي أرباح الاستثماراتاستراتيجيريالكلما زاد كان أفضلربع سنويتقرير بإيرادات ومصروفات الإستثمارات الماليةإدارة الإستدامة0103500000
A13: م2 | B13: م1-2 | C13: عدد مصادر الدخل (الجديدة) | D13: استراتيجي | E13: مصدر دخل | F13: كلما زاد كان أفضل | G13: ربع سنوي | H13: تقرير بمصادر الدخل الجديدة وإيراداتها | I13: إدارة الإتصال المؤسسي | J13: 0 | K13: 1 | L13: 0 | M13: 0 | N13: =IF(AND($T13="معتمد",$L13>0),$M13/$L13,"") | O13: =IF($T13="معتمد",$M13-$L13,"") | P13: =IF(AND($T13="معتمد",$L13>0),($M13-$L13)/$L13,"") | Q13: لا يوجد لهذا الربع | R13: لا يوجد لهذا الربع | V13: =IF($T13<>"معتمد","",IFERROR((IF(AND($T13="معتمد",$L13>0),$M13,0))/(IF(AND($T13="معتمد",$L13>0),$L13,0)),"")) | W13: =IF(AND($T13="معتمد",$K13>0),(IF($T13="معتمد",$M13,0))/$K13,"") | X13: =A13&B13&C13&D13&E13&F13&G13&H13&I13&J13&K13&L13&M13&N13&O13&P13&Q13&R13&S13&T13&U13&V13&W13 -> م2م1-2عدد مصادر الدخل (الجديدة)استراتيجيمصدر دخلكلما زاد كان أفضلربع سنويتقرير بمصادر الدخل الجديدة وإيراداتهاإدارة الإتصال المؤسسي0100لا يوجد لهذا الربعلا يوجد لهذا الربع
A14: م2 | B14: م2-2 | C14: إجمالي الإيرادات من مصادر الدخل الجديدة | D14: استراتيجي | E14: ريال | F14: كلما زاد كان أفضل | G14: ربع سنوي | H14: تقرير مالي بالإيرادات المالية للجمعية | I14: إدارة الإتصال المؤسسي | J14: 0 | K14: 50000 | L14: 0 | M14: 0 | N14: =IF(AND($T14="معتمد",$L14>0),$M14/$L14,"") | O14: =IF($T14="معتمد",$M14-$L14,"") | P14: =IF(AND($T14="معتمد",$L14>0),($M14-$L14)/$L14,"") | Q14: لا يوجد لهذا الربع | R14: لا يوجد لهذا الربع | V14: =IF($T14<>"معتمد","",IFERROR((IF(AND($T14="معتمد",$L14>0),$M14,0))/(IF(AND($T14="معتمد",$L14>0),$L14,0)),"")) | W14: =IF(AND($T14="معتمد",$K14>0),(IF($T14="معتمد",$M14,0))/$K14,"") | X14: =A14&B14&C14&D14&E14&F14&G14&H14&I14&J14&K14&L14&M14&N14&O14&P14&Q14&R14&S14&T14&U14&V14&W14 -> م2م2-2إجمالي الإيرادات من مصادر الدخل الجديدةاستراتيجيريالكلما زاد كان أفضلربع سنويتقرير مالي بالإيرادات المالية للجمعيةإدارة الإتصال المؤسسي05000000لا يوجد لهذا الربعلا يوجد لهذا الربع
A15: م2 | B15: م3-2 | C15: إجمالي التبرعات | D15: استراتيجي | E15: ريال | F15: كلما زاد كان أفضل | G15: ربع سنوي | H15: تقرير مالي بالتبرعات في الفترة الحالية والفترة السابقة | I15: إدارة الإتصال المؤسسي | J15: 0 | K15: 0 | L15: 0 | N15: =IF(AND($T15="معتمد",$L15>0),$M15/$L15,"") | O15: =IF($T15="معتمد",$M15-$L15,"") | P15: =IF(AND($T15="معتمد",$L15>0),($M15-$L15)/$L15,"") | Q15: المالية | R15: المالية | V15: =IF($T15<>"معتمد","",IFERROR((IF(AND($T15="معتمد",$L15>0),$M15,0))/(IF(AND($T15="معتمد",$L15>0),$L15,0)),"")) | W15: =IF(AND($T15="معتمد",$K15>0),(IF($T15="معتمد",$M15,0))/$K15,"") | X15: =A15&B15&C15&D15&E15&F15&G15&H15&I15&J15&K15&L15&M15&N15&O15&P15&Q15&R15&S15&T15&U15&V15&W15 -> م2م3-2إجمالي التبرعاتاستراتيجيريالكلما زاد كان أفضلربع سنويتقرير مالي بالتبرعات في الفترة الحالية والفترة السابقةإدارة الإتصال المؤسسي000الماليةالمالية
A16: د1 | B16: د1-1 | C16: عدد البرامج المبتكرة التي تم تصميمها | D16: استراتيجي | E16: برامج | F16: كلما زاد كان أفضل | G16: ربع سنوي | H16: قائمة بالبرامج التي صممتها الجمعية | I16: إدارة الرعاية و التمكين،إدارة التكافل المجتمعي | J16: 0 | K16: 14 | L16: 5 | M16: 2 | N16: =IF(AND($T16="معتمد",$L16>0),$M16/$L16,"") | O16: =IF($T16="معتمد",$M16-$L16,"") | P16: =IF(AND($T16="معتمد",$L16>0),($M16-$L16)/$L16,"") | Q16: أولاً:تم العمل على برنامج مسيرة التعليم كبرنامج مبتكر يهدف إلى اكتشاف مهارات ومواهب الأبناء من الأسر المستفيدة، حيث تم بناء وثيقة المشروع و اختيار مرشد مهني مناسب ، كما تم حصر الطلاب الموهوبين وإعداد ملفات إنجاز خاصة بهم تمهيدًا لتنمية مهاراتهم واستثمارها. ثانياً:تم العمل على إعداد وثيقة المشروع وخطة تنفيذية متكاملة لإقامة عيد الزاد بطريقة مبتكرة خلال هذا العام ، كما تم ربط عدد ( 30 ) اسرة من الاسر المستفيدة في الافطار الرمضاني لـــ مركز سواعد و أفكار للتدريب . | R16: اولاً:تم ذلك بدءًا من دراسة الاحتياج السنوي، ثم حصر الأبناء الذين لديهم مؤشرات للموهبة من خلال استبيانات مخصصة، تلاها التواصل مع كل موهوب وبناء ملف إنجاز خاص به يتضمن معلوماته ومجالات موهبته. كما عُقدت عدة اجتماعات مع عدد من المرشدين المهنيين لاختيار المرشد المناسب لتنفيذ البرنامج ودعم الأبناء في اكتشاف مهاراتهم وتنميتها. ثانياً:تم بناء وثيقة المشروع من خلال تحديد الأهداف والمخرجات والأنشطة، وجمع البيانات اللازمة، كما تم إعداد خطة تنفيذية متكاملة للقاء عيد الزاد تضمنت تحديد الفئة المستهدفة، والبرامج المصاحبة، والاحتياجات اللوجستية، واختيار القاعات المناسبة، بما يضمن تنفيذ اللقاء بطريقة مبتكرة. | S16: مؤشر عدد البرامج المبتكرة التي تم تصميمها | V16: =IF($T16<>"معتمد","",IFERROR((IF(AND($T16="معتمد",$L16>0),$M16,0))/(IF(AND($T16="معتمد",$L16>0),$L16,0)),"")) | W16: =IF(AND($T16="معتمد",$K16>0),(IF($T16="معتمد",$M16,0))/$K16,"") | X16: =A16&B16&C16&D16&E16&F16&G16&H16&I16&J16&K16&L16&M16&N16&O16&P16&Q16&R16&S16&T16&U16&V16&W16 -> د1د1-1عدد البرامج المبتكرة التي تم تصميمهااستراتيجيبرامجكلما زاد كان أفضلربع سنويقائمة بالبرامج التي صممتها الجمعيةإدارة الرعاية و التمكين،إدارة التكافل المجتمعي01452أولاً:تم العمل على برنامج مسيرة التعليم كبرنامج مبتكر يهدف إلى اكتشاف مهارات ومواهب الأبناء من الأسر المستفيدة، حيث تم بناء وثيقة المشروع و اختيار مرشد مهني مناسب ، كما تم حصر الطلاب الموهوبين وإعداد ملفات إنجاز خاصة بهم تمهيدًا لتنمية مهاراتهم واستثمارها. ثانياً:تم العمل على إعداد وثيقة المشروع وخطة تنفيذية متكاملة لإقامة عيد الزاد بطريقة مبتكرة خلال هذا العام ، كما تم ربط عدد ( 30 ) اسرة من الاسر المستفيدة في الافطار الرمضاني لـــ مركز سواعد و أفكار للتدريب .اولاً:تم ذلك بدءًا من دراسة الاحتياج السنوي، ثم حصر الأبناء الذين لديهم مؤشرات للموهبة من خلال استبيانات مخصصة، تلاها التواصل مع كل موهوب وبناء ملف إنجاز خاص به يتضمن معلوماته ومجالات موهبته. كما عُقدت عدة اجتماعات مع عدد من المرشدين المهنيين لاختيار المرشد المناسب لتنفيذ البرنامج ودعم الأبناء في اكتشاف مهاراتهم وتنميتها. ثانياً:تم بناء وثيقة المشروع من خلال تحديد الأهداف والمخرجات والأنشطة، وجمع البيانات اللازمة، كما تم إعداد خطة تنفيذية متكاملة للقاء عيد الزاد تضمنت تحديد الفئة المستهدفة، والبرامج المصاحبة، والاحتياجات اللوجستية، واختيار القاعات المناسبة، بما يضمن تنفيذ اللقاء بطريقة مبتكرة.مؤشر عدد البرامج المبتكرة التي تم تصميمها
A17: د1 | B17: د2-1 | C17: عدد الخدمات المبتكرة التي تم تصميمها | D17: استراتيجي | E17: خدمة | F17: كلما زاد كان أفضل | G17: ربع سنوي | H17: قائمة بالخدمات التي صممتها الجمعية | I17: إدارة الرعاية و التمكين،إدارة التكافل المجتمعي | J17: 0 | K17: 18 | L17: 5 | M17: 2 | N17: =IF(AND($T17="معتمد",$L17>0),$M17/$L17,"") | O17: =IF($T17="معتمد",$M17-$L17,"") | P17: =IF(AND($T17="معتمد",$L17>0),($M17-$L17)/$L17,"") | Q17: أولاً:تم إطلاق خدمة مبتكرة لربط الخريجين بالمرشد المهني، بهدف متابعة مسارهم التدريبي والمهني بشكل فردي وضمان توافق مهاراتهم مع الفرص المتاحة. ثانياً:تم اعداد خدمة التقارير الفردية لكل مشترك/ة في برنامج غِراس، والذي تضمن تقييم الحالة قبل و بعد المشاركة و مستوى التحسن و الأثر المتحقق على المشترك/ة. | R17: اولاً:تم ذلك من خلال التعاقد مع مرشد مهني متخصص، وحصر الدفعة الأولى من الخريجين بعدد ( 10 ) للربط المباشر بالمرشد، لضمان متابعة مسارهم التدريبي والمهني بشكل فردي وفعّال. ثانياً:تم ذلك عبر نماذج متابعة تزود للأكاديمات الشريكة و يتم متابعتها من قِبل فريق التمكين لضمان متابعة دقيقة وموثوقة للأثر . | S17: مؤشر عدد الخدمات المبتكرة التي تم تصميمها | V17: =IF($T17<>"معتمد","",IFERROR((IF(AND($T17="معتمد",$L17>0),$M17,0))/(IF(AND($T17="معتمد",$L17>0),$L17,0)),"")) | W17: =IF(AND($T17="معتمد",$K17>0),(IF($T17="معتمد",$M17,0))/$K17,"") | X17: =A17&B17&C17&D17&E17&F17&G17&H17&I17&J17&K17&L17&M17&N17&O17&P17&Q17&R17&S17&T17&U17&V17&W17 -> د1د2-1عدد الخدمات المبتكرة التي تم تصميمهااستراتيجيخدمةكلما زاد كان أفضلربع سنويقائمة بالخدمات التي صممتها الجمعيةإدارة الرعاية و التمكين،إدارة التكافل المجتمعي01852أولاً:تم إطلاق خدمة مبتكرة لربط الخريجين بالمرشد المهني، بهدف متابعة مسارهم التدريبي والمهني بشكل فردي وضمان توافق مهاراتهم مع الفرص المتاحة. ثانياً:تم اعداد خدمة التقارير الفردية لكل مشترك/ة في برنامج غِراس، والذي تضمن تقييم الحالة قبل و بعد المشاركة و مستوى التحسن و الأثر المتحقق على المشترك/ة.اولاً:تم ذلك من خلال التعاقد مع مرشد مهني متخصص، وحصر الدفعة الأولى من الخريجين بعدد ( 10 ) للربط المباشر بالمرشد، لضمان متابعة مسارهم التدريبي والمهني بشكل فردي وفعّال. ثانياً:تم ذلك عبر نماذج متابعة تزود للأكاديمات الشريكة و يتم متابعتها من قِبل فريق التمكين لضمان متابعة دقيقة وموثوقة للأثر .مؤشر عدد الخدمات المبتكرة التي تم تصميمها
A18: د2 | B18: د1-2 | C18: نسبة مصاريف البرامج والأنشطة إلى إجمالي المصاريف | D18: استراتيجي | E18: نسبة | F18: كلما زاد كان أفضل | G18: ربع سنوي | H18: تقرير مالي موضح فيه جميع المصروفات (المصروفات الإدارية والعمومية، مصروفات النشاط) | I18: إدارة الشؤون المالية و الإدارية | J18: 0 | K18: 0.85 | L18: 0.8 | N18: =IF(AND($T18="معتمد",$L18>0),$M18/$L18,"") | O18: =IF($T18="معتمد",$M18-$L18,"") | P18: =IF(AND($T18="معتمد",$L18>0),($M18-$L18)/$L18,"") | V18: =IF($T18<>"معتمد","",IFERROR((IF(AND($T18="معتمد",$L18>0),$M18,0))/(IF(AND($T18="معتمد",$L18>0),$L18,0)),"")) | W18: =IF(AND($T18="معتمد",$K18>0),(IF($T18="معتمد",$M18,0))/$K18,"") | X18: =A18&B18&C18&D18&E18&F18&G18&H18&I18&J18&K18&L18&M18&N18&O18&P18&Q18&R18&S18&T18&U18&V18&W18 -> د2د1-2نسبة مصاريف البرامج والأنشطة إلى إجمالي المصاريفاستراتيجينسبةكلما زاد كان أفضلربع سنويتقرير مالي موضح فيه جميع المصروفات (المصروفات الإدارية والعمومية، مصروفات النشاط)إدارة الشؤون المالية و الإدارية00.850.8
A19: د2 | B19: د2-2 | C19: عدد العمليات التي تم تجويدها (تطويرها) | D19: استراتيجي | E19: عملية | F19: كلما زاد كان أفضل | G19: ربع سنوي | H19: قائمة بالعمليات المطورة وبيان التطوير الذي تم عليها وتاريخ التطوير والإعتماد | I19: إدارة الشؤون المالية و الإدارية،إدارة الأداء و النمو | J19: 0 | K19: 1 | L19: 0 | N19: =IF(AND($T19="معتمد",$L19>0),$M19/$L19,"") | O19: =IF($T19="معتمد",$M19-$L19,"") | P19: =IF(AND($T19="معتمد",$L19>0),($M19-$L19)/$L19,"") | V19: =IF($T19<>"معتمد","",IFERROR((IF(AND($T19="معتمد",$L19>0),$M19,0))/(IF(AND($T19="معتمد",$L19>0),$L19,0)),"")) | W19: =IF(AND($T19="معتمد",$K19>0),(IF($T19="معتمد",$M19,0))/$K19,"") | X19: =A19&B19&C19&D19&E19&F19&G19&H19&I19&J19&K19&L19&M19&N19&O19&P19&Q19&R19&S19&T19&U19&V19&W19 -> د2د2-2عدد العمليات التي تم تجويدها (تطويرها)استراتيجيعمليةكلما زاد كان أفضلربع سنويقائمة بالعمليات المطورة وبيان التطوير الذي تم عليها وتاريخ التطوير والإعتمادإدارة الشؤون المالية و الإدارية،إدارة الأداء و النمو010
A20: د3 | B20: د1-3 | C20: نسبة نضج واستدامة البيئة التقنية | D20: استراتيجي | E20: نسبة | F20: كلما زاد كان أفضل | G20: ربع سنوي | H20: تقرير بالعمليات | I20: إدارة الشؤون المالية و الإدارية | J20: 0 | K20: 1 | L20: 0.95 | N20: =IF(AND($T20="معتمد",$L20>0),$M20/$L20,"") | O20: =IF($T20="معتمد",$M20-$L20,"") | P20: =IF(AND($T20="معتمد",$L20>0),($M20-$L20)/$L20,"") | V20: =IF($T20<>"معتمد","",IFERROR((IF(AND($T20="معتمد",$L20>0),$M20,0))/(IF(AND($T20="معتمد",$L20>0),$L20,0)),"")) | W20: =IF(AND($T20="معتمد",$K20>0),(IF($T20="معتمد",$M20,0))/$K20,"") | X20: =A20&B20&C20&D20&E20&F20&G20&H20&I20&J20&K20&L20&M20&N20&O20&P20&Q20&R20&S20&T20&U20&V20&W20 -> د3د1-3نسبة نضج واستدامة البيئة التقنيةاستراتيجينسبةكلما زاد كان أفضلربع سنويتقرير بالعملياتإدارة الشؤون المالية و الإدارية010.95
A21: د3 | B21: د2-3 | C21: نسبة العمليات التي تم تطويرها وفق معايير الجودة المعتمدة | D21: استراتيجي | E21: نسبة | F21: كلما زاد كان أفضل | G21: ربع سنوي | H21: تقرير بالعمليات | I21: إدارة الشؤون المالية و الإدارية | J21: 0 | K21: 0.8 | L21: 0.5 | N21: =IF(AND($T21="معتمد",$L21>0),$M21/$L21,"") | O21: =IF($T21="معتمد",$M21-$L21,"") | P21: =IF(AND($T21="معتمد",$L21>0),($M21-$L21)/$L21,"") | V21: =IF($T21<>"معتمد","",IFERROR((IF(AND($T21="معتمد",$L21>0),$M21,0))/(IF(AND($T21="معتمد",$L21>0),$L21,0)),"")) | W21: =IF(AND($T21="معتمد",$K21>0),(IF($T21="معتمد",$M21,0))/$K21,"") | X21: =A21&B21&C21&D21&E21&F21&G21&H21&I21&J21&K21&L21&M21&N21&O21&P21&Q21&R21&S21&T21&U21&V21&W21 -> د3د2-3نسبة العمليات التي تم تطويرها وفق معايير الجودة المعتمدةاستراتيجينسبةكلما زاد كان أفضلربع سنويتقرير بالعملياتإدارة الشؤون المالية و الإدارية00.80.5
A22: د4 | B22: د1-4 | C22: عدد الشراكات الفاعلة | D22: استراتيجي | E22: شراكة | F22: كلما زاد كان أفضل | G22: ربع سنوي | H22: قائمة ببيانات الشراكات الفاعلة التي أقامتها الجمعية | I22: إدارة الإتصال المؤسسي | J22: 0 | K22: 80 | L22: 25 | M22: 27 | N22: =IF(AND($T22="معتمد",$L22>0),$M22/$L22,"") | O22: =IF($T22="معتمد",$M22-$L22,"") | P22: =IF(AND($T22="معتمد",$L22>0),($M22-$L22)/$L22,"") | Q22: تجاوز المستهدف، حيث تم تحقيق 27 شراكة فاعلة مقابل 25 شراكة مستهدفة | R22: بسبب تكثيف جهود تفعيل الشراكات القائمة، وعقد شراكات جديدة خلال الفترة، مما أسهم في تجاوز المستهدف. | S22: https://alzaadsa-my.sharepoint.com/:x:/g/personal/pmo_alzaad_org_sa/IQB7vy07ymgcRJU2sFCDjBzTAeGhMft73-1Z23WQxuOkdHA?e=koPBpN | V22: =IF($T22<>"معتمد","",IFERROR((IF(AND($T22="معتمد",$L22>0),$M22,0))/(IF(AND($T22="معتمد",$L22>0),$L22,0)),"")) | W22: =IF(AND($T22="معتمد",$K22>0),(IF($T22="معتمد",$M22,0))/$K22,"") | X22: =A22&B22&C22&D22&E22&F22&G22&H22&I22&J22&K22&L22&M22&N22&O22&P22&Q22&R22&S22&T22&U22&V22&W22 -> د4د1-4عدد الشراكات الفاعلةاستراتيجيشراكةكلما زاد كان أفضلربع سنويقائمة ببيانات الشراكات الفاعلة التي أقامتها الجمعيةإدارة الإتصال المؤسسي0802527تجاوز المستهدف، حيث تم تحقيق 27 شراكة فاعلة مقابل 25 شراكة مستهدفةبسبب تكثيف جهود تفعيل الشراكات القائمة، وعقد شراكات جديدة خلال الفترة، مما أسهم في تجاوز المستهدف.https://alzaadsa-my.sharepoint.com/:x:/g/personal/pmo_alzaad_org_sa/IQB7vy07ymgcRJU2sFCDjBzTAeGhMft73-1Z23WQxuOkdHA?e=koPBpN
A23: د4 | B23: د2-4 | C23: عدد الزيارات المنفذة للشركاء وأصحاب المصلحة | D23: استراتيجي | E23: عدد | F23: كلما زاد كان أفضل | G23: ربع سنوي | H23: قائمة بالشركاء وأصحاب المصلحة الذين تم التواصل معهم بأسمائهم أو أوصافهم )مثال: قاعدة بيانات الواتس – شركاء منافذ( موضح بها العدد ووسيلة التواصل) | I23: إدارة الإتصال المؤسسي | J23: 0 | K23: 52 زيارة،4 عمليات تواصل | L23: 24 | N23: =IF(AND($T23="معتمد",$L23>0),$M23/$L23,"") | O23: =IF($T23="معتمد",$M23-$L23,"") | P23: =IF(AND($T23="معتمد",$L23>0),($M23-$L23)/$L23,"") | S23: https://alzaadsa-my.sharepoint.com/:x:/g/personal/yousefalmuaiouf_alzaad_org_sa/IQAQ2zUsxLyKRqWVoDs908tUAbjUVPVsKrm86YCwYspPbEk?e=8Nntxp | V23: =IF($T23<>"معتمد","",IFERROR((IF(AND($T23="معتمد",$L23>0),$M23,0))/(IF(AND($T23="معتمد",$L23>0),$L23,0)),"")) | W23: =IF(AND($T23="معتمد",$K23>0),(IF($T23="معتمد",$M23,0))/$K23,"") | X23: =A23&B23&C23&D23&E23&F23&G23&H23&I23&J23&K23&L23&M23&N23&O23&P23&Q23&R23&S23&T23&U23&V23&W23 -> د4د2-4عدد الزيارات المنفذة للشركاء وأصحاب المصلحة استراتيجيعددكلما زاد كان أفضلربع سنويقائمة بالشركاء وأصحاب المصلحة الذين تم التواصل معهم بأسمائهم أو أوصافهم )مثال: قاعدة بيانات الواتس – شركاء منافذ( موضح بها العدد ووسيلة التواصل)إدارة الإتصال المؤسسي052 زيارة،4 عمليات تواصل24https://alzaadsa-my.sharepoint.com/:x:/g/personal/yousefalmuaiouf_alzaad_org_sa/IQAQ2zUsxLyKRqWVoDs908tUAbjUVPVsKrm86YCwYspPbEk?e=8Nntxp
A24: د4 | B24: د3-4 | C24: نسبة رضا أصحاب المصلحة عن الجمعية | D24: استراتيجي | E24: نسبة | F24: كلما زاد كان أفضل | G24: ربع سنوي | H24: إستمارات قياس رضا أصحاب المصلحة عن الجمعية | I24: إدارة الإتصال المؤسسي | J24: 0 | K24: 0.94 | L24: 0 | M24: قياس نصفي | N24: =IF(AND($T24="معتمد",$L24>0),$M24/$L24,"") | O24: =IF($T24="معتمد",$M24-$L24,"") | P24: =IF(AND($T24="معتمد",$L24>0),($M24-$L24)/$L24,"") | V24: =IF($T24<>"معتمد","",IFERROR((IF(AND($T24="معتمد",$L24>0),$M24,0))/(IF(AND($T24="معتمد",$L24>0),$L24,0)),"")) | W24: =IF(AND($T24="معتمد",$K24>0),(IF($T24="معتمد",$M24,0))/$K24,"") | X24: =A24&B24&C24&D24&E24&F24&G24&H24&I24&J24&K24&L24&M24&N24&O24&P24&Q24&R24&S24&T24&U24&V24&W24 -> د4د3-4نسبة رضا أصحاب المصلحة عن الجمعيةاستراتيجينسبةكلما زاد كان أفضلربع سنويإستمارات قياس رضا أصحاب المصلحة عن الجمعيةإدارة الإتصال المؤسسي00.940قياس نصفي
A25: د5 | B25: د1-5 | C25: عدد المشاركات الإعلامية التي تخدم أهداف الجمعية | D25: استراتيجي | E25: مشاركة إعلامية | F25: كلما زاد كان أفضل | G25: ربع سنوي | H25: تقرير بالمشاركات الإعلامية التي نشرتها الجمعية | I25: إدارة الإتصال المؤسسي | J25: 0 | K25: 200 | L25: 70 | M25: 77 | N25: =IF(AND($T25="معتمد",$L25>0),$M25/$L25,"") | O25: =IF($T25="معتمد",$M25-$L25,"") | P25: =IF(AND($T25="معتمد",$L25>0),($M25-$L25)/$L25,"") | Q25: تجاوز المستهدف | R25: بسبب كثرة البرامج والتقارير و تعدد منصات النشر | S25: https://alzaadsa-my.sharepoint.com/:x:/g/personal/pmo_alzaad_org_sa/IQDo-smBxou5RJXMyGYglAzCAaF2cTSRecZdS3gFJmFPBUk?e=BB1ZKd | V25: =IF($T25<>"معتمد","",IFERROR((IF(AND($T25="معتمد",$L25>0),$M25,0))/(IF(AND($T25="معتمد",$L25>0),$L25,0)),"")) | W25: =IF(AND($T25="معتمد",$K25>0),(IF($T25="معتمد",$M25,0))/$K25,"") | X25: =A25&B25&C25&D25&E25&F25&G25&H25&I25&J25&K25&L25&M25&N25&O25&P25&Q25&R25&S25&T25&U25&V25&W25 -> د5د1-5عدد المشاركات الإعلامية التي تخدم أهداف الجمعيةاستراتيجيمشاركة إعلاميةكلما زاد كان أفضلربع سنويتقرير بالمشاركات الإعلامية التي نشرتها الجمعيةإدارة الإتصال المؤسسي02007077تجاوز المستهدف بسبب كثرة البرامج والتقارير و تعدد منصات النشر https://alzaadsa-my.sharepoint.com/:x:/g/personal/pmo_alzaad_org_sa/IQDo-smBxou5RJXMyGYglAzCAaF2cTSRecZdS3gFJmFPBUk?e=BB1ZKd
A26: د5 | B26: د2-5 | C26: عدد مرات الظهور الإعلامي (المشاهدات) | D26: استراتيجي | E26: مشاهدة | F26: كلما زاد كان أفضل | G26: ربع سنوي | H26: تقرير بالمشاهدات للمشاركات الإعلامية، بتوضيح كل قناة وعدد المشاهدات / الظهور فيها | I26: إدارة الإتصال المؤسسي | J26: 0 | K26: 5000000 | L26: 2500000 | M26: 891,001 | N26: =IF(AND($T26="معتمد",$L26>0),$M26/$L26,"") | O26: =IF($T26="معتمد",$M26-$L26,"") | P26: =IF(AND($T26="معتمد",$L26>0),($M26-$L26)/$L26,"") | Q26: أقل من المستهدف | R26: الرقم جيد ولكن المستهدف كبير | S26: https://alzaadsa-my.sharepoint.com/:x:/g/personal/pmo_alzaad_org_sa/IQBUK_2ZwxVnSJVTBIzV_hsZAXgJc30bu00sFkZ6RSRG_-M?e=rvEBgA | V26: =IF($T26<>"معتمد","",IFERROR((IF(AND($T26="معتمد",$L26>0),$M26,0))/(IF(AND($T26="معتمد",$L26>0),$L26,0)),"")) | W26: =IF(AND($T26="معتمد",$K26>0),(IF($T26="معتمد",$M26,0))/$K26,"") | X26: =A26&B26&C26&D26&E26&F26&G26&H26&I26&J26&K26&L26&M26&N26&O26&P26&Q26&R26&S26&T26&U26&V26&W26 -> د5د2-5عدد مرات الظهور الإعلامي (المشاهدات) استراتيجيمشاهدةكلما زاد كان أفضلربع سنويتقرير بالمشاهدات للمشاركات الإعلامية، بتوضيح كل قناة وعدد المشاهدات / الظهور فيهاإدارة الإتصال المؤسسي050000002500000891,001 أقل من المستهدف الرقم جيد ولكن المستهدف كبيرhttps://alzaadsa-my.sharepoint.com/:x:/g/personal/pmo_alzaad_org_sa/IQBUK_2ZwxVnSJVTBIzV_hsZAXgJc30bu00sFkZ6RSRG_-M?e=rvEBgA
A27: د5 | B27: د3-5 | C27: عدد قنوات الظهور الإعلامي | D27: استراتيجي | E27: قناة | F27: كلما زاد كان أفضل | G27: ربع سنوي | H27: قائمة بالقنوات الإعلامية | I27: إدارة الإتصال المؤسسي | J27: 0 | K27: 20 | L27: 20 | M27: 26 | N27: =IF(AND($T27="معتمد",$L27>0),$M27/$L27,"") | O27: =IF($T27="معتمد",$M27-$L27,"") | P27: =IF(AND($T27="معتمد",$L27>0),($M27-$L27)/$L27,"") | Q27: أكثر من المستهدف | R27: وجود برامج ومبادرت جلبت قنوات ظهور جديدة | S27: https://alzaadsa-my.sharepoint.com/:x:/g/personal/pmo_alzaad_org_sa/IQCu-MV0BSBXQaE85-rKFY1DARFC1aDayyX5MG4joqFuHJA?e=N3ZOlw | V27: =IF($T27<>"معتمد","",IFERROR((IF(AND($T27="معتمد",$L27>0),$M27,0))/(IF(AND($T27="معتمد",$L27>0),$L27,0)),"")) | W27: =IF(AND($T27="معتمد",$K27>0),(IF($T27="معتمد",$M27,0))/$K27,"") | X27: =A27&B27&C27&D27&E27&F27&G27&H27&I27&J27&K27&L27&M27&N27&O27&P27&Q27&R27&S27&T27&U27&V27&W27 -> د5د3-5عدد قنوات الظهور الإعلامياستراتيجيقناةكلما زاد كان أفضلربع سنويقائمة بالقنوات الإعلاميةإدارة الإتصال المؤسسي0202026أكثر من المستهدفوجود برامج ومبادرت جلبت قنوات ظهور جديدة https://alzaadsa-my.sharepoint.com/:x:/g/personal/pmo_alzaad_org_sa/IQCu-MV0BSBXQaE85-rKFY1DARFC1aDayyX5MG4joqFuHJA?e=N3ZOlw
A28: ن1 | B28: ن1-1 | C28: متوسط عدد الساعات التطويرية المقدمة للفرد | D28: استراتيجي | E28: ساعة | F28: كلما زاد كان أفضل | G28: ربع سنوي | H28: تقرير بالساعات التطويرية المقدمة لموظفي الجمعية ونوع التطوير المقدم | I28: إدارة الأداء و النمو | J28: 0 | K28: 50 | L28: 10 | N28: =IF(AND($T28="معتمد",$L28>0),$M28/$L28,"") | O28: =IF($T28="معتمد",$M28-$L28,"") | P28: =IF(AND($T28="معتمد",$L28>0),($M28-$L28)/$L28,"") | V28: =IF($T28<>"معتمد","",IFERROR((IF(AND($T28="معتمد",$L28>0),$M28,0))/(IF(AND($T28="معتمد",$L28>0),$L28,0)),"")) | W28: =IF(AND($T28="معتمد",$K28>0),(IF($T28="معتمد",$M28,0))/$K28,"") | X28: =A28&B28&C28&D28&E28&F28&G28&H28&I28&J28&K28&L28&M28&N28&O28&P28&Q28&R28&S28&T28&U28&V28&W28 -> ن1ن1-1متوسط عدد الساعات التطويرية المقدمة للفرداستراتيجيساعةكلما زاد كان أفضلربع سنويتقرير بالساعات التطويرية المقدمة لموظفي الجمعية ونوع التطوير المقدمإدارة الأداء و النمو05010
A29: ن1 | B29: ن2-1 | C29: نسبة الموظفين المؤهلين مهنيًا في وظائفهم | D29: استراتيجي | E29: نسبة | F29: كلما زاد كان أفضل | G29: ربع سنوي | H29: تقرير بالموظفين الحاصلين على التأهيل وخطط الإحتياج المهني لهم | I29: إدارة الأداء و النمو | J29: 0 | K29: 0.65 | L29: 0.45 | N29: =IF(AND($T29="معتمد",$L29>0),$M29/$L29,"") | O29: =IF($T29="معتمد",$M29-$L29,"") | P29: =IF(AND($T29="معتمد",$L29>0),($M29-$L29)/$L29,"") | V29: =IF($T29<>"معتمد","",IFERROR((IF(AND($T29="معتمد",$L29>0),$M29,0))/(IF(AND($T29="معتمد",$L29>0),$L29,0)),"")) | W29: =IF(AND($T29="معتمد",$K29>0),(IF($T29="معتمد",$M29,0))/$K29,"") | X29: =A29&B29&C29&D29&E29&F29&G29&H29&I29&J29&K29&L29&M29&N29&O29&P29&Q29&R29&S29&T29&U29&V29&W29 -> ن1ن2-1نسبة الموظفين المؤهلين مهنيًا في وظائفهماستراتيجينسبةكلما زاد كان أفضلربع سنويتقرير بالموظفين الحاصلين على التأهيل وخطط الإحتياج المهني لهمإدارة الأداء و النمو00.650.45
A30: ن2 | B30: ن1-2 | C30: عدد المتطوعين في أعمال وبرامج الجمعية (بدون تكرار) | D30: استراتيجي | E30: متطوع | F30: كلما زاد كان أفضل | G30: ربع سنوي | H30: تقرير بأسماء المشاريع أو البرامج التي شارك فيها متطوعون وعددهم + تقرير بالمتطوعين المشاركين في إدارات الجمعية | I30: إدارة التكافل المجتمعي | J30: 0 | K30: 2500 | L30: 1300 | M30: 968 | N30: =IF(AND($T30="معتمد",$L30>0),$M30/$L30,"") | O30: =IF($T30="معتمد",$M30-$L30,"") | P30: =IF(AND($T30="معتمد",$L30>0),($M30-$L30)/$L30,"") | Q30: تم تسجيل (968) متطوعًا في أعمال وبرامج الجمعية خلال الربع الأول من عام 2026، بدون تكرار، وهو ما يمثل نسبة تحقق بلغت (38.7%) من المستهدف السنوي البالغ (2500) متطوع. | R30: من خلال تفعيل منصة التطوع وتسجيل المتطوعين في برامج الجمعية المختلفة، وحصر أسماء المتطوعين المشاركين في إدارات الجمعية وبرامجها، وإعداد تقرير موحد بأسماء المشاريع والبرامج التي شارك فيها متطوعون وعددهم بدون تكرار. | S30: https://alzaadsa-my.sharepoint.com/:x:/g/personal/fatimahalfahhad_alzaad_org_sa/IQAn5SLQ8esGR4bRNysz8R17AZJZE6_VY_rFI-8WfuEWaSw?e=WbIIKZ | V30: =IF($T30<>"معتمد","",IFERROR((IF(AND($T30="معتمد",$L30>0),$M30,0))/(IF(AND($T30="معتمد",$L30>0),$L30,0)),"")) | W30: =IF(AND($T30="معتمد",$K30>0),(IF($T30="معتمد",$M30,0))/$K30,"") | X30: =A30&B30&C30&D30&E30&F30&G30&H30&I30&J30&K30&L30&M30&N30&O30&P30&Q30&R30&S30&T30&U30&V30&W30 -> ن2ن1-2عدد المتطوعين في أعمال وبرامج الجمعية (بدون تكرار)استراتيجيمتطوعكلما زاد كان أفضلربع سنويتقرير بأسماء المشاريع أو البرامج التي شارك فيها متطوعون وعددهم + تقرير بالمتطوعين المشاركين في إدارات الجمعيةإدارة التكافل المجتمعي025001300968تم تسجيل (968) متطوعًا في أعمال وبرامج الجمعية خلال الربع الأول من عام 2026، بدون تكرار، وهو ما يمثل نسبة تحقق بلغت (38.7%) من المستهدف السنوي البالغ (2500) متطوع.من خلال تفعيل منصة التطوع وتسجيل المتطوعين في برامج الجمعية المختلفة، وحصر أسماء المتطوعين المشاركين في إدارات الجمعية وبرامجها، وإعداد تقرير موحد بأسماء المشاريع والبرامج التي شارك فيها متطوعون وعددهم بدون تكرار.https://alzaadsa-my.sharepoint.com/:x:/g/personal/fatimahalfahhad_alzaad_org_sa/IQAn5SLQ8esGR4bRNysz8R17AZJZE6_VY_rFI-8WfuEWaSw?e=WbIIKZ
A31: ن2 | B31: ن2-2 | C31: عدد الساعات التطوعية | D31: استراتيجي | E31: ساعة | F31: كلما زاد كان أفضل | G31: ربع سنوي | H31: تقرير بالساعات التطوعية التي تم تسجيلها منصة التطوع + (من لم تنطبق عليه الشروط) | I31: إدارة التكافل المجتمعي | J31: 0 | K31: 70000 | L31: 32000 | M31: 47274 | N31: =IF(AND($T31="معتمد",$L31>0),$M31/$L31,"") | O31: =IF($T31="معتمد",$M31-$L31,"") | P31: =IF(AND($T31="معتمد",$L31>0),($M31-$L31)/$L31,"") | Q31: تم تسجيل (47274) ساعة تطوعية خلال الربع الأول من عام 2026، وهو ما يمثل نسبة تحقق بلغت (62.3%) من المستهدف للربع الأول البالغ (32,000) ساعة، وتجاوز المستهدف الربعي بفارق (15,274) ساعة. | R31: من خلال تسجيل الساعات التطوعية عبر منصة التطوع الرسمية، وإضافة ساعات المتطوعين الذين لم تنطبق عليهم شروط المنصة يدويًا، وتجميع التقارير الدورية من الإدارات والبرامج المختلفة لاستخراج إجمالي الساعات التطوعية المنجزة خلال الربع الأول. | S31: https://alzaadsa-my.sharepoint.com/:x:/g/personal/fatimahalfahhad_alzaad_org_sa/IQAn5SLQ8esGR4bRNysz8R17AZJZE6_VY_rFI-8WfuEWaSw?e=WbIIKZ | V31: =IF($T31<>"معتمد","",IFERROR((IF(AND($T31="معتمد",$L31>0),$M31,0))/(IF(AND($T31="معتمد",$L31>0),$L31,0)),"")) | W31: =IF(AND($T31="معتمد",$K31>0),(IF($T31="معتمد",$M31,0))/$K31,"") | X31: =A31&B31&C31&D31&E31&F31&G31&H31&I31&J31&K31&L31&M31&N31&O31&P31&Q31&R31&S31&T31&U31&V31&W31 -> ن2ن2-2عدد الساعات التطوعيةاستراتيجيساعةكلما زاد كان أفضلربع سنويتقرير بالساعات التطوعية التي تم تسجيلها منصة التطوع + (من لم تنطبق عليه الشروط)إدارة التكافل المجتمعي0700003200047274تم تسجيل (47274) ساعة تطوعية خلال الربع الأول من عام 2026، وهو ما يمثل نسبة تحقق بلغت (62.3%) من المستهدف للربع الأول البالغ (32,000) ساعة، وتجاوز المستهدف الربعي بفارق (15,274) ساعة.من خلال تسجيل الساعات التطوعية عبر منصة التطوع الرسمية، وإضافة ساعات المتطوعين الذين لم تنطبق عليهم شروط المنصة يدويًا، وتجميع التقارير الدورية من الإدارات والبرامج المختلفة لاستخراج إجمالي الساعات التطوعية المنجزة خلال الربع الأول.https://alzaadsa-my.sharepoint.com/:x:/g/personal/fatimahalfahhad_alzaad_org_sa/IQAn5SLQ8esGR4bRNysz8R17AZJZE6_VY_rFI-8WfuEWaSw?e=WbIIKZ
A32: ن3 | B32: ن1-3 | C32: نسبة رضا العاملين عن بيئة العمل | D32: استراتيجي | E32: نسبة | F32: كلما زاد كان أفضل | G32: ربع سنوي | H32: إستمارات قياس رضا العاملين | I32: إدارة الأداء و النمو | J32: 0 | K32: 0.88 | L32: 0.85 | N32: =IF(AND($T32="معتمد",$L32>0),$M32/$L32,"") | O32: =IF($T32="معتمد",$M32-$L32,"") | P32: =IF(AND($T32="معتمد",$L32>0),($M32-$L32)/$L32,"") | V32: =IF($T32<>"معتمد","",IFERROR((IF(AND($T32="معتمد",$L32>0),$M32,0))/(IF(AND($T32="معتمد",$L32>0),$L32,0)),"")) | W32: =IF(AND($T32="معتمد",$K32>0),(IF($T32="معتمد",$M32,0))/$K32,"") | X32: =A32&B32&C32&D32&E32&F32&G32&H32&I32&J32&K32&L32&M32&N32&O32&P32&Q32&R32&S32&T32&U32&V32&W32 -> ن3ن1-3نسبة رضا العاملين عن بيئة العمل استراتيجينسبةكلما زاد كان أفضلربع سنويإستمارات قياس رضا العاملينإدارة الأداء و النمو00.880.85
